2023-03-30 07:43:51,988:WARNING:discord.client: PyNaCl is not installed, voice will NOT be supported
2023-03-30 07:43:52,859:DEBUG:discord.client: on_ready has successfully been registered as an event
2023-03-30 07:43:52,890:DEBUG:discord.client: on_message has successfully been registered as an event
2023-03-30 07:43:52,933:INFO:discord.client: logging in using static token
2023-03-30 07:43:58,529:INFO:discord.gateway: Shard ID None has connected to Gateway (Session ID: 939f438cb262bee2f190c81d48c6b6fe).
2023-03-30 08:05:49,432:ERROR:discord.client: Attempting a reconnect in 0.50s
Traceback (most recent call last):
  File "C:\Users\aaren\AppData\Local\Programs\Python\Python39\lib\site-packages\aiohttp\connector.py", line 1152, in _create_direct_connection
    hosts = await asyncio.shield(host_resolved)
  File "C:\Users\aaren\AppData\Local\Programs\Python\Python39\lib\site-packages\aiohttp\connector.py", line 874, in _resolve_host
    addrs = await self._resolver.resolve(host, port, family=self._family)
  File "C:\Users\aaren\AppData\Local\Programs\Python\Python39\lib\site-packages\aiohttp\resolver.py", line 33, in resolve
    infos = await self._loop.getaddrinfo(
  File "C:\Users\aaren\AppData\Local\Programs\Python\Python39\lib\asyncio\base_events.py", line 856, in getaddrinfo
    return await self.run_in_executor(
  File "C:\Users\aaren\AppData\Local\Programs\Python\Python39\lib\concurrent\futures\thread.py", line 52, in run
    result = self.fn(*self.args, **self.kwargs)
  File "C:\Users\aaren\AppData\Local\Programs\Python\Python39\lib\socket.py", line 953, in getaddrinfo
    for res in _socket.getaddrinfo(host, port, family, type, proto, flags):
socket.gaierror: [Errno 11001] getaddrinfo failed

The above exception was the direct cause of the following exception:

Traceback (most recent call last):
  File "C:\Users\aaren\AppData\Local\Programs\Python\Python39\lib\site-packages\discord\client.py", line 624, in connect
    self.ws = await asyncio.wait_for(coro, timeout=60.0)
  File "C:\Users\aaren\AppData\Local\Programs\Python\Python39\lib\asyncio\tasks.py", line 476, in wait_for
    return fut.result()
  File "C:\Users\aaren\AppData\Local\Programs\Python\Python39\lib\site-packages\discord\gateway.py", line 371, in from_client
    socket = await client.http.ws_connect(url)
  File "C:\Users\aaren\AppData\Local\Programs\Python\Python39\lib\site-packages\discord\http.py", line 536, in ws_connect
    return await self.__session.ws_connect(url, **kwargs)
  File "C:\Users\aaren\AppData\Local\Programs\Python\Python39\lib\site-packages\aiohttp\client.py", line 779, in _ws_connect
    resp = await self.request(
  File "C:\Users\aaren\AppData\Local\Programs\Python\Python39\lib\site-packages\aiohttp\client.py", line 536, in _request
    conn = await self._connector.connect(
  File "C:\Users\aaren\AppData\Local\Programs\Python\Python39\lib\site-packages\aiohttp\connector.py", line 540, in connect
    proto = await self._create_connection(req, traces, timeout)
  File "C:\Users\aaren\AppData\Local\Programs\Python\Python39\lib\site-packages\aiohttp\connector.py", line 901, in _create_connection
    _, proto = await self._create_direct_connection(req, traces, timeout)
  File "C:\Users\aaren\AppData\Local\Programs\Python\Python39\lib\site-packages\aiohttp\connector.py", line 1166, in _create_direct_connection
    raise ClientConnectorError(req.connection_key, exc) from exc
aiohttp.client_exceptions.ClientConnectorError: Cannot connect to host gateway-us-east1-d.discord.gg:443 ssl:default [getaddrinfo failed]
2023-03-30 08:05:50,212:ERROR:discord.client: Attempting a reconnect in 1.38s
Traceback (most recent call last):
  File "C:\Users\aaren\AppData\Local\Programs\Python\Python39\lib\site-packages\aiohttp\connector.py", line 1152, in _create_direct_connection
    hosts = await asyncio.shield(host_resolved)
  File "C:\Users\aaren\AppData\Local\Programs\Python\Python39\lib\site-packages\aiohttp\connector.py", line 874, in _resolve_host
    addrs = await self._resolver.resolve(host, port, family=self._family)
  File "C:\Users\aaren\AppData\Local\Programs\Python\Python39\lib\site-packages\aiohttp\resolver.py", line 33, in resolve
    infos = await self._loop.getaddrinfo(
  File "C:\Users\aaren\AppData\Local\Programs\Python\Python39\lib\asyncio\base_events.py", line 856, in getaddrinfo
    return await self.run_in_executor(
  File "C:\Users\aaren\AppData\Local\Programs\Python\Python39\lib\concurrent\futures\thread.py", line 52, in run
    result = self.fn(*self.args, **self.kwargs)
  File "C:\Users\aaren\AppData\Local\Programs\Python\Python39\lib\socket.py", line 953, in getaddrinfo
    for res in _socket.getaddrinfo(host, port, family, type, proto, flags):
socket.gaierror: [Errno 11001] getaddrinfo failed

The above exception was the direct cause of the following exception:

Traceback (most recent call last):
  File "C:\Users\aaren\AppData\Local\Programs\Python\Python39\lib\site-packages\discord\client.py", line 624, in connect
    self.ws = await asyncio.wait_for(coro, timeout=60.0)
  File "C:\Users\aaren\AppData\Local\Programs\Python\Python39\lib\asyncio\tasks.py", line 476, in wait_for
    return fut.result()
  File "C:\Users\aaren\AppData\Local\Programs\Python\Python39\lib\site-packages\discord\gateway.py", line 371, in from_client
    socket = await client.http.ws_connect(url)
  File "C:\Users\aaren\AppData\Local\Programs\Python\Python39\lib\site-packages\discord\http.py", line 536, in ws_connect
    return await self.__session.ws_connect(url, **kwargs)
  File "C:\Users\aaren\AppData\Local\Programs\Python\Python39\lib\site-packages\aiohttp\client.py", line 779, in _ws_connect
    resp = await self.request(
  File "C:\Users\aaren\AppData\Local\Programs\Python\Python39\lib\site-packages\aiohttp\client.py", line 536, in _request
    conn = await self._connector.connect(
  File "C:\Users\aaren\AppData\Local\Programs\Python\Python39\lib\site-packages\aiohttp\connector.py", line 540, in connect
    proto = await self._create_connection(req, traces, timeout)
  File "C:\Users\aaren\AppData\Local\Programs\Python\Python39\lib\site-packages\aiohttp\connector.py", line 901, in _create_connection
    _, proto = await self._create_direct_connection(req, traces, timeout)
  File "C:\Users\aaren\AppData\Local\Programs\Python\Python39\lib\site-packages\aiohttp\connector.py", line 1166, in _create_direct_connection
    raise ClientConnectorError(req.connection_key, exc) from exc
aiohttp.client_exceptions.ClientConnectorError: Cannot connect to host gateway-us-east1-d.discord.gg:443 ssl:default [getaddrinfo failed]
2023-03-30 08:05:53,266:INFO:discord.gateway: Shard ID None session has been invalidated.
2023-03-30 08:06:00,238:INFO:discord.gateway: Shard ID None has connected to Gateway (Session ID: b6303ba78f8a7f067a70433400cd8604).
2023-03-30 08:29:41,463:INFO:discord.gateway: Shard ID None has successfully RESUMED session b6303ba78f8a7f067a70433400cd8604.
2023-03-30 08:55:33,197:WARNING:discord.gateway: Shard ID None has stopped responding to the gateway. Closing and restarting.
2023-03-30 08:55:33,211:ERROR:discord.client: Attempting a reconnect in 1.80s
Traceback (most recent call last):
  File "C:\Users\aaren\AppData\Local\Programs\Python\Python39\lib\site-packages\aiohttp\connector.py", line 1152, in _create_direct_connection
    hosts = await asyncio.shield(host_resolved)
  File "C:\Users\aaren\AppData\Local\Programs\Python\Python39\lib\site-packages\aiohttp\connector.py", line 874, in _resolve_host
    addrs = await self._resolver.resolve(host, port, family=self._family)
  File "C:\Users\aaren\AppData\Local\Programs\Python\Python39\lib\site-packages\aiohttp\resolver.py", line 33, in resolve
    infos = await self._loop.getaddrinfo(
  File "C:\Users\aaren\AppData\Local\Programs\Python\Python39\lib\asyncio\base_events.py", line 856, in getaddrinfo
    return await self.run_in_executor(
  File "C:\Users\aaren\AppData\Local\Programs\Python\Python39\lib\concurrent\futures\thread.py", line 52, in run
    result = self.fn(*self.args, **self.kwargs)
  File "C:\Users\aaren\AppData\Local\Programs\Python\Python39\lib\socket.py", line 953, in getaddrinfo
    for res in _socket.getaddrinfo(host, port, family, type, proto, flags):
socket.gaierror: [Errno 11001] getaddrinfo failed

The above exception was the direct cause of the following exception:

Traceback (most recent call last):
  File "C:\Users\aaren\AppData\Local\Programs\Python\Python39\lib\site-packages\discord\client.py", line 624, in connect
    self.ws = await asyncio.wait_for(coro, timeout=60.0)
  File "C:\Users\aaren\AppData\Local\Programs\Python\Python39\lib\asyncio\tasks.py", line 476, in wait_for
    return fut.result()
  File "C:\Users\aaren\AppData\Local\Programs\Python\Python39\lib\site-packages\discord\gateway.py", line 371, in from_client
    socket = await client.http.ws_connect(url)
  File "C:\Users\aaren\AppData\Local\Programs\Python\Python39\lib\site-packages\discord\http.py", line 536, in ws_connect
    return await self.__session.ws_connect(url, **kwargs)
  File "C:\Users\aaren\AppData\Local\Programs\Python\Python39\lib\site-packages\aiohttp\client.py", line 779, in _ws_connect
    resp = await self.request(
  File "C:\Users\aaren\AppData\Local\Programs\Python\Python39\lib\site-packages\aiohttp\client.py", line 536, in _request
    conn = await self._connector.connect(
  File "C:\Users\aaren\AppData\Local\Programs\Python\Python39\lib\site-packages\aiohttp\connector.py", line 540, in connect
    proto = await self._create_connection(req, traces, timeout)
  File "C:\Users\aaren\AppData\Local\Programs\Python\Python39\lib\site-packages\aiohttp\connector.py", line 901, in _create_connection
    _, proto = await self._create_direct_connection(req, traces, timeout)
  File "C:\Users\aaren\AppData\Local\Programs\Python\Python39\lib\site-packages\aiohttp\connector.py", line 1166, in _create_direct_connection
    raise ClientConnectorError(req.connection_key, exc) from exc
aiohttp.client_exceptions.ClientConnectorError: Cannot connect to host gateway-us-east1-d.discord.gg:443 ssl:default [getaddrinfo failed]
2023-03-30 08:55:35,061:ERROR:discord.client: Attempting a reconnect in 0.87s
Traceback (most recent call last):
  File "C:\Users\aaren\AppData\Local\Programs\Python\Python39\lib\site-packages\aiohttp\connector.py", line 1152, in _create_direct_connection
    hosts = await asyncio.shield(host_resolved)
  File "C:\Users\aaren\AppData\Local\Programs\Python\Python39\lib\site-packages\aiohttp\connector.py", line 874, in _resolve_host
    addrs = await self._resolver.resolve(host, port, family=self._family)
  File "C:\Users\aaren\AppData\Local\Programs\Python\Python39\lib\site-packages\aiohttp\resolver.py", line 33, in resolve
    infos = await self._loop.getaddrinfo(
  File "C:\Users\aaren\AppData\Local\Programs\Python\Python39\lib\asyncio\base_events.py", line 856, in getaddrinfo
    return await self.run_in_executor(
  File "C:\Users\aaren\AppData\Local\Programs\Python\Python39\lib\concurrent\futures\thread.py", line 52, in run
    result = self.fn(*self.args, **self.kwargs)
  File "C:\Users\aaren\AppData\Local\Programs\Python\Python39\lib\socket.py", line 953, in getaddrinfo
    for res in _socket.getaddrinfo(host, port, family, type, proto, flags):
socket.gaierror: [Errno 11001] getaddrinfo failed

The above exception was the direct cause of the following exception:

Traceback (most recent call last):
  File "C:\Users\aaren\AppData\Local\Programs\Python\Python39\lib\site-packages\discord\client.py", line 624, in connect
    self.ws = await asyncio.wait_for(coro, timeout=60.0)
  File "C:\Users\aaren\AppData\Local\Programs\Python\Python39\lib\asyncio\tasks.py", line 476, in wait_for
    return fut.result()
  File "C:\Users\aaren\AppData\Local\Programs\Python\Python39\lib\site-packages\discord\gateway.py", line 371, in from_client
    socket = await client.http.ws_connect(url)
  File "C:\Users\aaren\AppData\Local\Programs\Python\Python39\lib\site-packages\discord\http.py", line 536, in ws_connect
    return await self.__session.ws_connect(url, **kwargs)
  File "C:\Users\aaren\AppData\Local\Programs\Python\Python39\lib\site-packages\aiohttp\client.py", line 779, in _ws_connect
    resp = await self.request(
  File "C:\Users\aaren\AppData\Local\Programs\Python\Python39\lib\site-packages\aiohttp\client.py", line 536, in _request
    conn = await self._connector.connect(
  File "C:\Users\aaren\AppData\Local\Programs\Python\Python39\lib\site-packages\aiohttp\connector.py", line 540, in connect
    proto = await self._create_connection(req, traces, timeout)
  File "C:\Users\aaren\AppData\Local\Programs\Python\Python39\lib\site-packages\aiohttp\connector.py", line 901, in _create_connection
    _, proto = await self._create_direct_connection(req, traces, timeout)
  File "C:\Users\aaren\AppData\Local\Programs\Python\Python39\lib\site-packages\aiohttp\connector.py", line 1166, in _create_direct_connection
    raise ClientConnectorError(req.connection_key, exc) from exc
aiohttp.client_exceptions.ClientConnectorError: Cannot connect to host gateway-us-east1-d.discord.gg:443 ssl:default [getaddrinfo failed]
2023-03-30 08:55:35,959:ERROR:discord.client: Attempting a reconnect in 4.61s
Traceback (most recent call last):
  File "C:\Users\aaren\AppData\Local\Programs\Python\Python39\lib\site-packages\aiohttp\connector.py", line 1152, in _create_direct_connection
    hosts = await asyncio.shield(host_resolved)
  File "C:\Users\aaren\AppData\Local\Programs\Python\Python39\lib\site-packages\aiohttp\connector.py", line 874, in _resolve_host
    addrs = await self._resolver.resolve(host, port, family=self._family)
  File "C:\Users\aaren\AppData\Local\Programs\Python\Python39\lib\site-packages\aiohttp\resolver.py", line 33, in resolve
    infos = await self._loop.getaddrinfo(
  File "C:\Users\aaren\AppData\Local\Programs\Python\Python39\lib\asyncio\base_events.py", line 856, in getaddrinfo
    return await self.run_in_executor(
  File "C:\Users\aaren\AppData\Local\Programs\Python\Python39\lib\concurrent\futures\thread.py", line 52, in run
    result = self.fn(*self.args, **self.kwargs)
  File "C:\Users\aaren\AppData\Local\Programs\Python\Python39\lib\socket.py", line 953, in getaddrinfo
    for res in _socket.getaddrinfo(host, port, family, type, proto, flags):
socket.gaierror: [Errno 11001] getaddrinfo failed

The above exception was the direct cause of the following exception:

Traceback (most recent call last):
  File "C:\Users\aaren\AppData\Local\Programs\Python\Python39\lib\site-packages\discord\client.py", line 624, in connect
    self.ws = await asyncio.wait_for(coro, timeout=60.0)
  File "C:\Users\aaren\AppData\Local\Programs\Python\Python39\lib\asyncio\tasks.py", line 476, in wait_for
    return fut.result()
  File "C:\Users\aaren\AppData\Local\Programs\Python\Python39\lib\site-packages\discord\gateway.py", line 371, in from_client
    socket = await client.http.ws_connect(url)
  File "C:\Users\aaren\AppData\Local\Programs\Python\Python39\lib\site-packages\discord\http.py", line 536, in ws_connect
    return await self.__session.ws_connect(url, **kwargs)
  File "C:\Users\aaren\AppData\Local\Programs\Python\Python39\lib\site-packages\aiohttp\client.py", line 779, in _ws_connect
    resp = await self.request(
  File "C:\Users\aaren\AppData\Local\Programs\Python\Python39\lib\site-packages\aiohttp\client.py", line 536, in _request
    conn = await self._connector.connect(
  File "C:\Users\aaren\AppData\Local\Programs\Python\Python39\lib\site-packages\aiohttp\connector.py", line 540, in connect
    proto = await self._create_connection(req, traces, timeout)
  File "C:\Users\aaren\AppData\Local\Programs\Python\Python39\lib\site-packages\aiohttp\connector.py", line 901, in _create_connection
    _, proto = await self._create_direct_connection(req, traces, timeout)
  File "C:\Users\aaren\AppData\Local\Programs\Python\Python39\lib\site-packages\aiohttp\connector.py", line 1166, in _create_direct_connection
    raise ClientConnectorError(req.connection_key, exc) from exc
aiohttp.client_exceptions.ClientConnectorError: Cannot connect to host gateway-us-east1-d.discord.gg:443 ssl:default [getaddrinfo failed]
2023-03-30 08:55:42,124:INFO:discord.gateway: Shard ID None session has been invalidated.
2023-03-30 08:55:48,582:INFO:discord.gateway: Shard ID None has connected to Gateway (Session ID: a6766d62f60bd2713c86843d3bd36a1f).
2023-03-30 08:56:31,438:ERROR:discord.client: Attempting a reconnect in 3.90s
Traceback (most recent call last):
  File "C:\Users\aaren\AppData\Local\Programs\Python\Python39\lib\site-packages\aiohttp\connector.py", line 1152, in _create_direct_connection
    hosts = await asyncio.shield(host_resolved)
  File "C:\Users\aaren\AppData\Local\Programs\Python\Python39\lib\site-packages\aiohttp\connector.py", line 874, in _resolve_host
    addrs = await self._resolver.resolve(host, port, family=self._family)
  File "C:\Users\aaren\AppData\Local\Programs\Python\Python39\lib\site-packages\aiohttp\resolver.py", line 33, in resolve
    infos = await self._loop.getaddrinfo(
  File "C:\Users\aaren\AppData\Local\Programs\Python\Python39\lib\asyncio\base_events.py", line 856, in getaddrinfo
    return await self.run_in_executor(
  File "C:\Users\aaren\AppData\Local\Programs\Python\Python39\lib\concurrent\futures\thread.py", line 52, in run
    result = self.fn(*self.args, **self.kwargs)
  File "C:\Users\aaren\AppData\Local\Programs\Python\Python39\lib\socket.py", line 953, in getaddrinfo
    for res in _socket.getaddrinfo(host, port, family, type, proto, flags):
socket.gaierror: [Errno 11001] getaddrinfo failed

The above exception was the direct cause of the following exception:

Traceback (most recent call last):
  File "C:\Users\aaren\AppData\Local\Programs\Python\Python39\lib\site-packages\discord\client.py", line 624, in connect
    self.ws = await asyncio.wait_for(coro, timeout=60.0)
  File "C:\Users\aaren\AppData\Local\Programs\Python\Python39\lib\asyncio\tasks.py", line 476, in wait_for
    return fut.result()
  File "C:\Users\aaren\AppData\Local\Programs\Python\Python39\lib\site-packages\discord\gateway.py", line 371, in from_client
    socket = await client.http.ws_connect(url)
  File "C:\Users\aaren\AppData\Local\Programs\Python\Python39\lib\site-packages\discord\http.py", line 536, in ws_connect
    return await self.__session.ws_connect(url, **kwargs)
  File "C:\Users\aaren\AppData\Local\Programs\Python\Python39\lib\site-packages\aiohttp\client.py", line 779, in _ws_connect
    resp = await self.request(
  File "C:\Users\aaren\AppData\Local\Programs\Python\Python39\lib\site-packages\aiohttp\client.py", line 536, in _request
    conn = await self._connector.connect(
  File "C:\Users\aaren\AppData\Local\Programs\Python\Python39\lib\site-packages\aiohttp\connector.py", line 540, in connect
    proto = await self._create_connection(req, traces, timeout)
  File "C:\Users\aaren\AppData\Local\Programs\Python\Python39\lib\site-packages\aiohttp\connector.py", line 901, in _create_connection
    _, proto = await self._create_direct_connection(req, traces, timeout)
  File "C:\Users\aaren\AppData\Local\Programs\Python\Python39\lib\site-packages\aiohttp\connector.py", line 1166, in _create_direct_connection
    raise ClientConnectorError(req.connection_key, exc) from exc
aiohttp.client_exceptions.ClientConnectorError: Cannot connect to host gateway-us-east1-d.discord.gg:443 ssl:default [getaddrinfo failed]
2023-03-30 08:56:42,290:INFO:discord.gateway: Shard ID None has successfully RESUMED session a6766d62f60bd2713c86843d3bd36a1f.
